<?xml version="1.0" ?>

<!--
  Gazebo ROS differential drive plugin 

  Try sending commands:

    ros2 topic pub /demo/cmd_vel geometry_msgs/Twist '{linear: {x: 0.05}}' -1

    ros2 topic pub /demo/cmd_vel geometry_msgs/Twist '{angular: {z: 0.1}}' -1

  Try listening to odometry:

    ros2 topic echo /demo/odom

  Try listening to TF:

    ros2 run tf2_ros tf2_echo odom base_link

    ros2 run tf2_ros tf2_echo base_link right_wheel

    ros2 run tf2_ros tf2_echo base_link left_wheel
-->

<sdf version="1.5">
  <model name="pioneer2dx">

    <link name="base_link">

      <pose>0 0 0.16 0 0 0</pose>
      <inertial>
        <mass>5.67</mass>
        <inertia>
          <ixx>0.07</ixx>
          <iyy>0.08</iyy>
          <izz>0.10</izz>
          <ixy>0</ixy>
          <ixz>0</ixz>
          <iyz>0</iyz>
        </inertia>
      </inertial>

      <collision name="collision">
        <geometry>
          <box>
            <size>0.445 0.277 0.17</size>
          </box>
        </geometry>
      </collision>
      <collision name="castor_collision">
        <pose>-0.200 0 -0.12 0 0 0</pose>
        <geometry>
          <sphere>
            <radius>0.04</radius>
          </sphere>
        </geometry>
        <surface>
          <friction>
            <ode>
              <mu>0</mu>
              <mu2>0</mu2>
              <slip1>1.0</slip1>
              <slip2>1.0</slip2>
            </ode>
          </friction>
        </surface>
      </collision>

      <visual name="visual">
        <pose>0 0 0.04 0 0 0</pose>
        <geometry>
          <mesh>
            <uri>model://pioneer2dx/meshes/chassis.dae</uri>
          </mesh>
        </geometry>
      </visual>

      <visual name="castor_visual">
        <pose>-0.200 0 -0.12 0 0 0</pose>
        <geometry>
          <sphere>
            <radius>0.04</radius>
          </sphere>
        </geometry>
        <material>
          <script>
            <uri>file://media/materials/scripts/gazebo.material</uri>
            <name>Gazebo/FlatBlack</name>
          </script>
        </material>
      </visual>
      
    </link>
    <link name="right_wheel">
      <pose>0.1 -.17 0.11 0 1.5707 1.5707</pose>
      <inertial>
        <mass>1.5</mass>
        <inertia>
          <ixx>0.0051</ixx>
          <iyy>0.0051</iyy>
          <izz>0.0090</izz>
          <ixy>0</ixy>
          <ixz>0</ixz>
          <iyz>0</iyz>
        </inertia>
      </inertial>
      <collision name="collision">
        <geometry>
          <cylinder>
            <radius>0.11</radius>
            <length>0.05</length>
          </cylinder>
        </geometry>
        <surface>
          <friction>
            <ode>
              <mu>100000.0</mu>
              <mu2>100000.0</mu2>
              <slip1>0.0</slip1>
              <slip2>0.0</slip2>
            </ode>
          </friction>
        </surface>
      </collision>
      <visual name="visual">
        <geometry>
          <cylinder>
            <radius>0.11</radius>
            <length>0.05</length>
          </cylinder>
        </geometry>
        <material>
          <script>
            <uri>file://media/materials/scripts/gazebo.material</uri>
            <name>Gazebo/FlatBlack</name>
          </script>
        </material>
      </visual>
    </link>

    <link name="left_wheel">
      <pose>0.1 .17 0.11 0 1.5707 1.5707</pose>
      <inertial>
        <mass>1.5</mass>
        <inertia>
          <ixx>0.0051</ixx>
          <iyy>0.0051</iyy>
          <izz>0.0090</izz>
          <ixy>0</ixy>
          <ixz>0</ixz>
          <iyz>0</iyz>
        </inertia>
      </inertial>
      <collision name="collision">
        <geometry>
          <cylinder>
            <radius>0.11</radius>
            <length>0.05</length>
          </cylinder>
        </geometry>
        <surface>
          <friction>
            <ode>
              <mu>100000.0</mu>
              <mu2>100000.0</mu2>
              <slip1>0.0</slip1>
              <slip2>0.0</slip2>
            </ode>
          </friction>
        </surface>
      </collision>
      <visual name="visual">
        <geometry>
          <cylinder>
            <radius>0.11</radius>
            <length>0.05</length>
          </cylinder>
        </geometry>
        <material>
          <script>
            <uri>file://media/materials/scripts/gazebo.material</uri>
            <name>Gazebo/FlatBlack</name>
          </script>
        </material>
      </visual>
    </link>

<!-- Add the laser range finder -->
       <link name="laser_link">
         <inertial>
           <!-- Mass of the laser range finder in kg -->
           <mass>0.1</mass>
         </inertial>
         <!-- Position is towards the front of the robot -->
         <!-- Laser finder is mounted on top -->
         <pose>0.15 0 0.30 0 0 0</pose>
         
         <!-- Add a mesh to make it more visually appealing -->
         <visual name="visual">
           <geometry>
             <mesh>
               <uri>model://hokuyo/meshes/hokuyo.dae</uri>
             </mesh>
           </geometry>
         </visual>
         
         <!-- Collision properties of the base of the laser range finder-->
         <collision name="collision-base">
           <pose>0 0 -0.0145 0 0 0</pose>
           <geometry>
             <box>
               <size>0.05 0.05 0.041</size>
             </box>
           </geometry>
         </collision>
         <!-- Collision properties of the top of the laser range finder-->
         <collision name="collision-top">
           <pose>0 0 0.0205 0 0 0</pose>
           <geometry>
             <cylinder>
               <radius>0.021</radius>
               <length>0.029</length>
             </cylinder>
           </geometry>
         </collision>

          <transform>
            <translation x="0.5" y="1.0" z="2.0" />
      <rotation roll="0.0" pitch="0.0" yaw="0.0" />
    </transform>
         
  <!-- Describes the type and properties of the sensor -->
	 <sensor name="laser" type="ray">
	   <pose>0.01 0 0.0175 0 -0 0</pose>
           <ray>
             <scan>
               <horizontal>
                 <samples>361</samples>
                 <resolution>1</resolution>
                 <min_angle>-3.14</min_angle>
                 <max_angle>3.14</max_angle>
               </horizontal>
             </scan>
             <range>
               <min>0.08</min>
               <max>2.5</max>
               <resolution>0.05</resolution>
             </range>
           </ray>
           <always_on>1</always_on>
           <update_rate>10</update_rate>
           <visualize>false</visualize>

           <plugin name='laser' filename='libgazebo_ros_ray_sensor.so'>
             <output_type>sensor_msgs/LaserScan</output_type>
           </plugin>
	 </sensor>
       </link>
    <!-- Connect laser range finder to the robot's body -->
    <joint type="fixed" name="laser_joint">
      <child>laser_link</child>
      <parent>base_link</parent>
    </joint>

    <joint type="revolute" name="left_wheel_hinge">
      <pose>0 0 -0.03 0 0 0</pose>
      <child>left_wheel</child>
      <parent>base_link</parent>
      <axis>
        <xyz>0 1 0</xyz>
        <use_parent_model_frame>true</use_parent_model_frame>
      </axis>
    </joint>
    <joint type="revolute" name="right_wheel_hinge">
      <pose>0 0 0.03 0 0 0</pose>
      <child>right_wheel</child>
      <parent>base_link</parent>
      <axis>
        <xyz>0 1 0</xyz>
        <use_parent_model_frame>true</use_parent_model_frame>
      </axis>
    </joint>

    <plugin filename="libDiffDrivePlugin.so" name="diff_drive">
      <left_joint>left_wheel_hinge</left_joint>
      <right_joint>right_wheel_hinge</right_joint>
      <torque>5</torque>
    </plugin>

    <!-- Controls the differential drive robot -->
    <plugin name='diff_drive' filename='libgazebo_ros_diff_drive.so'>
      <ros>
        <namespace>/demo</namespace>
        <remapping>cmd_vel:=cmd_vel</remapping>
        <remapping>odom:=odom</remapping>
      </ros>

      <!-- wheels -->
      <left_joint>left_wheel_hinge</left_joint>
      <right_joint>right_wheel_hinge</right_joint>

      <!-- kinematics -->
      <wheel_separation>0.39</wheel_separation>
      <wheel_diameter>0.15</wheel_diameter>

      <!-- limits -->
      <wheelAcceleration>0</wheelAcceleration>
      <wheelTorque>20</wheelTorque>
      
      <!-- output -->
      <publish_odom>true</publish_odom>
      <publish_odom_tf>true</publish_odom_tf>
      <publish_wheel_tf>true</publish_wheel_tf>

      <odometry_frame>odom</odometry_frame>
      <robot_base_frame>base_link</robot_base_frame>
    </plugin> 
  </model>
</sdf>
